2022-10-27 13:55:41,389 - INFO - PlanckX Web3 Service Started.
2022-10-27 13:55:43,232 - INFO - PlanckX Web3 Service Started.
2022-10-27 14:01:38,222 - ERROR - Traceback (most recent call last):
  File "J:\job_code\planckx_web3\main.py", line 243, in transfer
    json_response['body']['resultHash'] = txHash
UnboundLocalError: local variable 'txHash' referenced before assignment

2022-10-27 14:02:08,652 - INFO - PlanckX Web3 Service Started.
2022-10-27 14:02:10,754 - INFO - PlanckX Web3 Service Started.
2022-10-27 14:02:16,288 - INFO - PlanckX Web3 Service Started.
2022-10-27 14:04:19,404 - ERROR - Traceback (most recent call last):
  File "J:\job_code\planckx_web3\main.py", line 243, in transfer
    return json.dumps(json_response)
  File "C:\ProgramData\Anaconda3\lib\json\__init__.py", line 231, in dumps
    return _default_encoder.encode(obj)
  File "C:\ProgramData\Anaconda3\lib\json\encoder.py", line 199, in encode
    chunks = self.iterencode(o, _one_shot=True)
  File "C:\ProgramData\Anaconda3\lib\json\encoder.py", line 257, in iterencode
    return _iterencode(o, 0)
  File "C:\ProgramData\Anaconda3\lib\json\encoder.py", line 179, in default
    raise TypeError(f'Object of type {o.__class__.__name__} '
TypeError: Object of type InvalidAddress is not JSON serializable

2022-10-27 14:04:22,614 - INFO - PlanckX Web3 Service Started.
2022-10-27 14:05:43,847 - INFO - PlanckX Web3 Service Started.
2022-10-27 14:05:45,807 - INFO - PlanckX Web3 Service Started.
2022-10-27 14:08:14,406 - ERROR - Traceback (most recent call last):
  File "J:\job_code\planckx_web3\main.py", line 243, in transfer
    return json.dumps(json_response)
  File "C:\ProgramData\Anaconda3\lib\json\__init__.py", line 231, in dumps
    return _default_encoder.encode(obj)
  File "C:\ProgramData\Anaconda3\lib\json\encoder.py", line 199, in encode
    chunks = self.iterencode(o, _one_shot=True)
  File "C:\ProgramData\Anaconda3\lib\json\encoder.py", line 257, in iterencode
    return _iterencode(o, 0)
  File "C:\ProgramData\Anaconda3\lib\json\encoder.py", line 179, in default
    raise TypeError(f'Object of type {o.__class__.__name__} '
TypeError: Object of type InvalidAddress is not JSON serializable

2022-10-27 14:09:13,361 - INFO - PlanckX Web3 Service Started.
2022-10-27 14:09:15,163 - INFO - PlanckX Web3 Service Started.
2022-10-27 14:16:19,203 - INFO - PlanckX Web3 Service Started.
2022-10-27 14:17:06,873 - INFO - PlanckX Web3 Service Started.
2022-10-27 14:19:04,893 - INFO - PlanckX Web3 Service Started.
2022-10-27 14:19:35,357 - INFO - PlanckX Web3 Service Started.
2022-10-27 14:31:29,733 - INFO - PlanckX Web3 Service Started.
2022-10-27 14:31:32,011 - INFO - PlanckX Web3 Service Started.
2022-10-27 14:31:43,531 - INFO - PlanckX Web3 Service Started.
2022-10-27 14:32:15,091 - INFO - PlanckX Web3 Service Started.
2022-10-27 14:32:17,013 - INFO - PlanckX Web3 Service Started.
2022-10-27 14:38:50,550 - INFO - PlanckX Web3 Service Started.
2022-10-27 14:50:07,623 - INFO - PlanckX Web3 Service Started.
2022-10-27 14:52:35,140 - INFO - PlanckX Web3 Service Started.
2022-10-27 14:53:38,370 - INFO - PlanckX Web3 Service Started.
2022-10-27 14:53:52,508 - INFO - PlanckX Web3 Service Started.
2022-10-27 14:53:54,757 - INFO - PlanckX Web3 Service Started.
2022-10-27 14:54:55,303 - INFO - PlanckX Web3 Service Started.
2022-10-27 14:55:20,159 - INFO - PlanckX Web3 Service Started.
2022-10-27 14:56:20,049 - INFO - PlanckX Web3 Service Started.
2022-10-27 14:57:10,099 - INFO - PlanckX Web3 Service Started.
2022-10-27 14:59:58,626 - INFO - PlanckX Web3 Service Started.
2022-10-27 15:02:38,901 - INFO - PlanckX Web3 Service Started.
2022-10-27 15:03:02,697 - INFO - PlanckX Web3 Service Started.
2022-10-27 15:03:09,084 - ERROR - Traceback (most recent call last):
  File "J:\job_code\planckx_web3\main.py", line 360, in burn
    return json.dumps(json_response)
  File "C:\ProgramData\Anaconda3\lib\json\__init__.py", line 231, in dumps
    return _default_encoder.encode(obj)
  File "C:\ProgramData\Anaconda3\lib\json\encoder.py", line 199, in encode
    chunks = self.iterencode(o, _one_shot=True)
  File "C:\ProgramData\Anaconda3\lib\json\encoder.py", line 257, in iterencode
    return _iterencode(o, 0)
  File "C:\ProgramData\Anaconda3\lib\json\encoder.py", line 179, in default
    raise TypeError(f'Object of type {o.__class__.__name__} '
TypeError: Object of type ValueError is not JSON serializable

2022-10-27 15:05:47,021 - INFO - PlanckX Web3 Service Started.
2022-10-27 15:05:49,061 - INFO - PlanckX Web3 Service Started.
2022-10-27 15:06:19,759 - INFO - PlanckX Web3 Service Started.
2022-10-27 15:07:58,342 - INFO - PlanckX Web3 Service Started.
2022-10-27 15:08:00,241 - INFO - PlanckX Web3 Service Started.
2022-10-27 15:08:07,557 - INFO - PlanckX Web3 Service Started.
2022-10-27 15:19:12,698 - INFO - PlanckX Web3 Service Started.
2022-10-27 15:21:00,116 - INFO - PlanckX Web3 Service Started.
2022-10-27 15:22:35,727 - INFO - PlanckX Web3 Service Started.
2022-10-27 15:26:05,014 - INFO - PlanckX Web3 Service Started.
2022-10-27 15:26:26,266 - INFO - PlanckX Web3 Service Started.
2022-10-27 15:27:42,372 - INFO - PlanckX Web3 Service Started.
2022-10-27 15:27:44,224 - INFO - PlanckX Web3 Service Started.
2022-10-27 15:28:00,924 - ERROR - Traceback (most recent call last):
  File "J:\job_code\planckx_web3\main.py", line 361, in burn
    return json.dumps(json_response)
  File "C:\ProgramData\Anaconda3\lib\json\__init__.py", line 231, in dumps
    return _default_encoder.encode(obj)
  File "C:\ProgramData\Anaconda3\lib\json\encoder.py", line 199, in encode
    chunks = self.iterencode(o, _one_shot=True)
  File "C:\ProgramData\Anaconda3\lib\json\encoder.py", line 257, in iterencode
    return _iterencode(o, 0)
  File "C:\ProgramData\Anaconda3\lib\json\encoder.py", line 179, in default
    raise TypeError(f'Object of type {o.__class__.__name__} '
TypeError: Object of type ValidationError is not JSON serializable

2022-10-27 15:28:04,024 - INFO - PlanckX Web3 Service Started.
2022-10-27 15:30:37,827 - INFO - PlanckX Web3 Service Started.
2022-10-27 15:30:39,659 - INFO - PlanckX Web3 Service Started.
2022-10-27 15:32:38,645 - INFO - PlanckX Web3 Service Started.
2022-10-27 15:33:55,897 - INFO - PlanckX Web3 Service Started.
2022-10-27 15:34:24,989 - INFO - PlanckX Web3 Service Started.
2022-10-27 15:34:54,595 - INFO - PlanckX Web3 Service Started.
2022-10-27 15:37:59,916 - INFO - PlanckX Web3 Service Started.
2022-10-27 15:41:14,143 - INFO - PlanckX Web3 Service Started.
2022-10-27 15:52:06,669 - INFO - PlanckX Web3 Service Started.
2022-10-27 16:06:18,184 - INFO - PlanckX Web3 Service Started.
2022-10-27 16:07:02,898 - INFO - Create ERC20 new address.
2022-10-27 16:07:04,085 - INFO - {'state': 200, 'msg': 'Successful', 'body': {'time': 1666858022, 'address': '0x40a1Ff27c27360BA4C65bc8c0962ED81D3a1bB4a', 'status': 'NEW'}}
2022-10-27 16:43:17,130 - INFO - PlanckX Web3 Service Started.
2022-10-27 16:46:28,245 - INFO - PlanckX Web3 Service Started.
2022-10-27 16:47:05,127 - INFO - PlanckX Web3 Service Started.
2022-10-27 16:48:16,252 - INFO - PlanckX Web3 Service Started.
2022-10-27 16:49:55,721 - INFO - PlanckX Web3 Service Started.
2022-10-27 16:51:23,944 - ERROR - Traceback (most recent call last):
  File "C:\Users\masai\AppData\Roaming\Python\Python37\site-packages\web3\contract.py", line 1537, in call_contract_function
    output_data = web3.codec.decode_abi(output_types, return_data)
  File "C:\Users\masai\AppData\Roaming\Python\Python37\site-packages\eth_abi\codec.py", line 196, in decode_abi
    return self.decode(types, data)
  File "C:\Users\masai\AppData\Roaming\Python\Python37\site-packages\eth_abi\codec.py", line 210, in decode
    return decoder(stream)
  File "C:\Users\masai\AppData\Roaming\Python\Python37\site-packages\eth_abi\decoding.py", line 127, in __call__
    return self.decode(stream)
  File "c:\programdata\anaconda3\lib\site-packages\eth_utils\functional.py", line 45, in inner
    return callback(fn(*args, **kwargs))
  File "C:\Users\masai\AppData\Roaming\Python\Python37\site-packages\eth_abi\decoding.py", line 173, in decode
    yield decoder(stream)
  File "C:\Users\masai\AppData\Roaming\Python\Python37\site-packages\eth_abi\decoding.py", line 127, in __call__
    return self.decode(stream)
  File "C:\Users\masai\AppData\Roaming\Python\Python37\site-packages\eth_abi\decoding.py", line 198, in decode
    raw_data = self.read_data_from_stream(stream)
  File "C:\Users\masai\AppData\Roaming\Python\Python37\site-packages\eth_abi\decoding.py", line 308, in read_data_from_stream
    len(data),
eth_abi.exceptions.InsufficientDataBytes: Tried to read 32 bytes.  Only got 0 bytes

The above exception was the direct cause of the following exception:

Traceback (most recent call last):
  File "J:/job_code/planckx_web3/main.py", line 137, in balanceOf
    balance = eth_api.getBalanceByToken(address, symbolOrAddr, chain)
  File "J:\job_code\planckx_web3\eth_api.py", line 77, in getBalanceByToken
    balance = contract.functions.balanceOf(address).call()
  File "C:\Users\masai\AppData\Roaming\Python\Python37\site-packages\web3\contract.py", line 981, in call
    **self.kwargs
  File "C:\Users\masai\AppData\Roaming\Python\Python37\site-packages\web3\contract.py", line 1554, in call_contract_function
    raise BadFunctionCallOutput(msg) from e
web3.exceptions.BadFunctionCallOutput: Could not transact with/call contract function, is contract deployed correctly and chain synced?

2022-10-27 16:55:04,790 - ERROR - Traceback (most recent call last):
  File "J:/job_code/planckx_web3/main.py", line 168, in getDecimals
    eth_api.tokenContractInfo(symbolOrAddr, chain)
  File "J:\job_code\planckx_web3\eth_api.py", line 145, in tokenContractInfo
    totalSupply = contract.functions.totalSupply().call()
AttributeError: 'ValueError' object has no attribute 'functions'

2022-10-27 16:55:13,686 - ERROR - Traceback (most recent call last):
  File "C:\Users\masai\AppData\Roaming\Python\Python37\site-packages\web3\contract.py", line 1537, in call_contract_function
    output_data = web3.codec.decode_abi(output_types, return_data)
  File "C:\Users\masai\AppData\Roaming\Python\Python37\site-packages\eth_abi\codec.py", line 196, in decode_abi
    return self.decode(types, data)
  File "C:\Users\masai\AppData\Roaming\Python\Python37\site-packages\eth_abi\codec.py", line 210, in decode
    return decoder(stream)
  File "C:\Users\masai\AppData\Roaming\Python\Python37\site-packages\eth_abi\decoding.py", line 127, in __call__
    return self.decode(stream)
  File "c:\programdata\anaconda3\lib\site-packages\eth_utils\functional.py", line 45, in inner
    return callback(fn(*args, **kwargs))
  File "C:\Users\masai\AppData\Roaming\Python\Python37\site-packages\eth_abi\decoding.py", line 173, in decode
    yield decoder(stream)
  File "C:\Users\masai\AppData\Roaming\Python\Python37\site-packages\eth_abi\decoding.py", line 127, in __call__
    return self.decode(stream)
  File "C:\Users\masai\AppData\Roaming\Python\Python37\site-packages\eth_abi\decoding.py", line 198, in decode
    raw_data = self.read_data_from_stream(stream)
  File "C:\Users\masai\AppData\Roaming\Python\Python37\site-packages\eth_abi\decoding.py", line 308, in read_data_from_stream
    len(data),
eth_abi.exceptions.InsufficientDataBytes: Tried to read 32 bytes.  Only got 0 bytes

The above exception was the direct cause of the following exception:

Traceback (most recent call last):
  File "J:/job_code/planckx_web3/main.py", line 168, in getDecimals
    eth_api.tokenContractInfo(symbolOrAddr, chain)
  File "J:\job_code\planckx_web3\eth_api.py", line 145, in tokenContractInfo
    totalSupply = contract.functions.totalSupply().call()
  File "C:\Users\masai\AppData\Roaming\Python\Python37\site-packages\web3\contract.py", line 981, in call
    **self.kwargs
  File "C:\Users\masai\AppData\Roaming\Python\Python37\site-packages\web3\contract.py", line 1554, in call_contract_function
    raise BadFunctionCallOutput(msg) from e
web3.exceptions.BadFunctionCallOutput: Could not transact with/call contract function, is contract deployed correctly and chain synced?

2022-10-27 16:55:42,330 - ERROR - Traceback (most recent call last):
  File "C:\Users\masai\AppData\Roaming\Python\Python37\site-packages\web3\contract.py", line 1537, in call_contract_function
    output_data = web3.codec.decode_abi(output_types, return_data)
  File "C:\Users\masai\AppData\Roaming\Python\Python37\site-packages\eth_abi\codec.py", line 196, in decode_abi
    return self.decode(types, data)
  File "C:\Users\masai\AppData\Roaming\Python\Python37\site-packages\eth_abi\codec.py", line 210, in decode
    return decoder(stream)
  File "C:\Users\masai\AppData\Roaming\Python\Python37\site-packages\eth_abi\decoding.py", line 127, in __call__
    return self.decode(stream)
  File "c:\programdata\anaconda3\lib\site-packages\eth_utils\functional.py", line 45, in inner
    return callback(fn(*args, **kwargs))
  File "C:\Users\masai\AppData\Roaming\Python\Python37\site-packages\eth_abi\decoding.py", line 173, in decode
    yield decoder(stream)
  File "C:\Users\masai\AppData\Roaming\Python\Python37\site-packages\eth_abi\decoding.py", line 127, in __call__
    return self.decode(stream)
  File "C:\Users\masai\AppData\Roaming\Python\Python37\site-packages\eth_abi\decoding.py", line 198, in decode
    raw_data = self.read_data_from_stream(stream)
  File "C:\Users\masai\AppData\Roaming\Python\Python37\site-packages\eth_abi\decoding.py", line 308, in read_data_from_stream
    len(data),
eth_abi.exceptions.InsufficientDataBytes: Tried to read 32 bytes.  Only got 0 bytes

The above exception was the direct cause of the following exception:

Traceback (most recent call last):
  File "J:/job_code/planckx_web3/main.py", line 168, in getDecimals
    eth_api.tokenContractInfo(symbolOrAddr, chain)
  File "J:\job_code\planckx_web3\eth_api.py", line 145, in tokenContractInfo
    totalSupply = contract.functions.totalSupply().call()
  File "C:\Users\masai\AppData\Roaming\Python\Python37\site-packages\web3\contract.py", line 981, in call
    **self.kwargs
  File "C:\Users\masai\AppData\Roaming\Python\Python37\site-packages\web3\contract.py", line 1554, in call_contract_function
    raise BadFunctionCallOutput(msg) from e
web3.exceptions.BadFunctionCallOutput: Could not transact with/call contract function, is contract deployed correctly and chain synced?

2022-10-27 17:01:54,735 - INFO - PlanckX Web3 Service Started.
2022-10-27 17:20:06,548 - INFO - PlanckX Web3 Service Started.
2022-10-27 17:37:52,970 - INFO - PlanckX Web3 Service Started.
